Workbook

Sheet ProgramEmail Details
A1: Template v 6.3
B2: Answers | C2: Notes | D2: Owner
A3: General Program Information
A4: Project Brief | C4: Link to brief if available Required for emails with Dynamic content | D4: DEM
A5: Program's Persistant Details | B5: https://docs.google.com/spreadsheets/d/1WQMNaAgEyscqaI80XXc-lHGu1Un7Ogt1jeA1AWvwrLE/edit#gid=0 | C5: Central document with information on all program's persistant information including sender info, sender name, and email lists for friendlies and final send. | D5: DEM
A6: Brand Status Sheet | C6: Link to your brand's status sheet with details on the email's timeline, contacts, etc | D6: DEM
A7: WIP BRD folder | C7: Link to your WIP folder with your program's relevant supporting documents | D7: DEM
A8: XD UI Kit | C8: Link to the XD UI Kit this email will leverage | D8: DEM
A9: Safety Fragments | C9: Link to the safety fragment folder this email will leverage | D9: DEM
A10: RM Development Resources Link | B10: https://drive.google.com/drive/folders/1_HsKoGYpnAezRWK9rk5CmlVxa0ULqOTt | C10: This folder houses best practices, onboarding materials, submission guidance, etc | D10: DEM
A11: Email Details
A12: Email Name | B12: Perjeta/Phesgo Dual Micro Campaign (Label Update) | C12: Name your email and use the same name across your FDS, email calendar, gCampaign, etc. | D12: DEM
A13: Email Marketing Unit | B13: Phesgo/Perjeta | C13: Provide the marketing unit that should be used when creating a tactic code for this email | D13: DEM
A14: Is the Email and/or VAE responsive? | B14: Yes | D14: DEM
A15: Is a Third Party screenshot needed? | B15: Yes | D15: DEM
A16: Is the Rep Connect CTA Included? | B16: No | D16: DEM
A17: Email Type (Ad hoc, Cadenced, Real-Time, VAE, 3rd Party) | B17: 3rd Party, House | C17: List all that apply: Ad hoc, Cadenced, Real-time, VAE, 3rd party Example: Cadenced, Real-Time | D17: DEM
A18: Email Audience | B18: HCP | C18: Select the audience this email is for | D18: DEM
A19: House Email Asset Code | B19: per-h-pmc-0001-2, per-h-pmc-0001-2-tp | C19: Refer to asset codes article for more info | D19: DEM
A20: VAE Email Asset Code | B20: per-h-pmc-0001-1-fe | D20: DEM
A21: Previous Asset Code | B21: N/A | C21: If leveraging a previous asset for the update provide asset code Inizio should reference | D21: DEM
A22: House Ad Hoc Email Specifications (N/A for VAEs) *Cadenced & real-time email specifics are defined in the Fulfillment Details Sheet
A23: Target Audience
A24: Override Domain 'Email Type' Suppression? (N/A for VAE) Should be 'No' unless this is a PAYUHCPRM or Cross-Portfolio safety and disaster email deployment that requires an exception | B24: No | C24: If this is a PAYUHCPRM or Cross-Portfolio safety and disaster email deployment and you are unsure if it should have an exception to this suppression, partner with XO Leadership | D24: DEM
A25: Ad Hoc List or CDP Audience Activation? Omni use cases will always use CDP and will not use an ad hoc list | D25: DEM
A26: Ad Hoc List Name (N/A for VAEs & CDP Audience Activation) | C26: Defined in Program RM BRD Example: Avastin HCP Branded | D26: DEM
A27: Ad Hoc Fulfillment Rules (N/A for VAEs & CDP Audience Activation) | C27: May not be applicable, only add if special rule(s) that aren't already defined in Program RM BRD need to be applied Example: Suppress users that opened original email sent on X date | D27: DEM
A28: Dynamic Content (If applicable)
A29: Estimated Dynamic Content Variables Count | C29: Max number of Dynamic Content Variables is 50. Example: 26 DEM to provide estimated count. Epsilon to populate the final count of dynamic variables on the "Deployment Details" tab once dynamic content fields have been shared. | D29: DEM
A30: Ad Hoc Testing Specifications
A31: Will email have an A/B test? | C31: Indicate Yes or No if this email will be an A/B test | D31: DEM
A32: Test Plan | C32: How the list should be split for the test and final deployments. Examples: 50/50, 10/10/80, 25/25/50, 10/10/10/70 | D32: DEM
A33: Test List Size | C33: Add the size of the test lists Example: Test lists should be 2,000 for each test group; final deploy to remainder of list | D33: DEM
A34: Ad Hoc Redeploy Specifications
A35: Ad Hoc Redeploy? | D35: DEM
A36: Suppressions | C36: Indicate Yes or No with details (opens, clicks) | D36: DEM
A37: New subject line and tactic code: Indicate Y or N | C37: If Yes, indicate subject line on Production Details Tab, row 38 Anytime the subject line changes, a new Tactic Code is used | D37: DEM
A38: Include new program enrollees since initial deploy | D38: DEM

Sheet Pre-Open Package
C2: For House/3rd Party PRC Submissions: Collapse row 1 if you are working on a VAE Collapse column B before downloading as a PDF
A3: Document Number: | B3: M-US-00029496(v2.0) | C3: e.g M-US-XXXXXXXX(vX.0)
A5: Sender Name: | B5: Genentech Oncology | C5: AOR to populate, DEM to validate against PPD e.g. Genentech Oncology Remove if 3rd Party email
A6: Sender Email: | B6: Oncology@e.genentech.com Oncology@mail.genentech.com | C6: AOR to populate, DEM to validate against PPD Only change the part before the @ symbol e.g. oncology@e.genentech.com Remove if 3rd Party email
A8: To: | B8: John Doe <john.doe@example.com> | C8: Do not update
C9: Provide up to a max of 3 subject line options for each of the emails Subject Line Best Practice - Keep 50 characters or less Length:
A10: Subject Line Option 1: | B10: Review survival and safety data in 1L HER2+ MBC | C10: =LEN(B10) -> 47
A11: Subject Line Option 2: | B11: See survival and safety data. Learn about a 1L HER2+ MBC treatment | C11: =LEN(B11) -> 66
A12: Subject Line Option 3: | B12: How do survival and safety data guide your treatment strategy? | C12: =LEN(B12) -> 62
A13: Subject Line Option 4: | B13: Treatment choices start with knowing survival and safety data
A14: Subject Line Option 5: | B14: What’s your induction-maintenance strategy in 1L HER2+ MBC?
A15: Subject Line Option 6: | B15: What guides your induction-maintenance choices?
A16: Subject Line Option 7: | B16: Explore a 1L HER2+ MBC treatment
C17: Preheader text should work accordingly with your subject line Preheader Best Practice - Keep 50-100 characters
A18: Preheader Text Option 1: | B18: Review data for a treatment option
A19: Preheader Text Option 2: | B19: Explore a treatment option
A20: Preheader Text Option 3: | B20: See the data to help plan your treatment in 1L HER2+ MBC
A21: Preheader Text Option 4: | B21: Inform your strategy in 1L HER2+ MBC
A22: Preheader Text Option 5: | B22: Review data for a treatment option
A23: Preheader Text Option 6: | B23: Explore the data of an option in 1L HER2+ MBC
A24: Preheader Text Option 7: | B24: See the data to help plan your strategy | C24: =LEN(B24) -> 39
C25: =LEN(B25) -> 0
C31: For VAE PRC Submissions: Collapse row 17 if you are working on a House or 3rd party email Collapse column B before downloading as a PDF
A32: Document Number: | B32: [] | C32: e.g. M-US-XXXXXXXX(vX.0)
A35: From: | B35: rep-email@gene.com | C35: Do not update
A36: To: | B36: John Doe <john.doe@example.com | C36: Do not update
C38: Add additional SL options as needed Subject Line Best Practice - Keep 50 characters or less Length:
A39: Subject Line Option 1: | C39: =LEN(B39) -> 0
A40: Subject Line Option 2: | C40: =LEN(B40) -> 0
A41: Subject Line Option 3: | C41: =LEN(B41) -> 0
A43: Placeholder Rep Message {{VeevaRepMessage}} | B43: [Dear/Hello/Greetings/Good Morning/Good Afternoon/Hi] [Dr./Mr./Ms.] [FirstName/LastName] [Customize this paragraph in line with the direction provided in the accompanying Field Direction Memo. Information should be limited to greeting and should contain no product claims.] [Full Name] [Title] [Genentech] [Mobile (XXX) XXX-XXXX] [Email] | C43: Do not update Commercial VAEs Only This needs to be included for Regulatory review and should not be updated. Any custom language provided by Marketing should go in the Field DIrection Memo (FDM)

Sheet CreativeLink MatrixAlt Text
A1: For PRC submissions only links and alt text should be included: - Do not delete any rows as it will break formulas on other tabs - Hide rows that should not be included with submission by right clicking on the row and select "Hide row" - Download tab as a PDF by opening up "File", select "Download" and select "PDF Document" - Once complete remember to unhide all rows
A2: HANDOFF PACKAGES
B3: Answers | D3: Notes | G3: Owner
A4: House/3rd Party Email
A5: Related Epic Number Note: do not format as link to Jira ticket | B5: RMEM-9118 | D5: DEM to populate for AOR to use in the Digital Handoff form submission Example: RMEM-345 | G5: DEM
A6: Delivery Objective | B6: Driver | D6: AOR to populate based on campaign delivery objective, as defined with Marketing in the Brand ICT. Values should be "Driver" or "Stand-alone" | G6: AOR
A7: Google Drive Folder for Dev-Ready House Email Package | B7: 2 Asset Handoff | D7: Pulls through to Production Details tab | G7: DEM
A8: Google Drive Folder for House Email's AFD File | B8: 4. PRC_RegA_FDA | D8: Pulls through to Production Details tab Specify VVPM code for this email asset if you have multiple files in your folder Can be same location Google Drive Folder for Dev-Ready Package | G8: DEM
A9: Veeva Approved Email (VAE)
A10: Related Epic Number Note: do not format as link to Jira ticket | B10: RMEM-9118 | D10: DEM to populate for AOR to use in the Digital Handoff form submission Example: RMEM-345 | G10: DEM
A11: Delivery Objective | D11: AOR to populate based on campaign delivery objective, as defined with Marketing in the Brand ICT. Values should be "Driver" or "Stand-alone" | G11: AOR
A12: VAE Template Name | D12: This is what will appear in VAE that users (field teams) see and identify the email by Collaborate with Marketing + RM DEM to pull through template name best practices | G12: AOR
A13: Maximum Number of Email Fragments (Optional) | D13: Enter the maximum number of email fragments allowed to be included in one VAE. We recommend not including more than 8. | G13: AOR
A14: VAE Email Fragment 1 Name | D14: This is what users (field teams) see and identify the email fragment by. Collaborate with Marketing + RM DEM to align on a user-friendly name. Limit is 100 characters. List in the order that they should appear. Duplicate row as needed. | G14: AOR
A15: VAE Email Fragment 2 Name | D15: This is what users (field teams) see and identify the email fragment by. Collaborate with Marketing + RM DEM to align on a user-friendly name. Limit is 100 characters. List in the order that they should appear. Duplicate row as needed. | G15: AOR
A16: Google Drive Folder for Dev-Ready VAE Package | B16: 2 Asset Handoff | D16: Pulls through to Production Details tab | G16: DEM
A17: Google Drive Folder for VAE's AFD File | B17: 5. Third Party Handoff | D17: Pulls through to Production Details tab Specify VVPM code for this email asset if you have multiple files in your folder Can be same location Google Drive Folder for Dev-Ready Package | G17: DEM
A18: ACCESSIBILITY: This section should only be completed for emails with visual accessibility as a focus. Discuss with your DEM prior to completing.
B19: Answers | D19: Notes | G19: Owner
A20: Apply Hover State to Buttons Note: Recommended for emails where visual accessibility is a priority | B20: no | D20: If yes is selected, hover state will be applied to all buttons in email Coordinate with DEM & Inizio | G20: AOR
A21: Hover State Color - Hex Value | D21: Provide hex value for the color that the buttons should be when hovered over. The pre-hover state color should be indicated in the PSD. Example: #FF5733 | G21: AOR
A22: LINK MATRIX
A23: Text of Link Add/delete lines to capture all text links within the email. All links included below must be specified and present in your email and email fragments. Image links should be added under alt text section. | B23: Final Destination URL Provide full URL of where the link drives to Links should represent final destination and not redirect Important: Indicate if Links are http:// or https:// | D23: Link Location Indicate everywhere in the email an item should be linked. For email fragments, indicate the fragment # with the fragment name, e.g. "Fragment 1 Fragment Name" | E23: Notes | G23: Owner
A24: Text Links: Header
A25: [View in web browser] | B25: No action needed - Dev and deploy agency to manage | E25: DO NOT REMOVE THIS LINE | G25: Inizio/ Epsilon
A26: PERJETA Prescribing Information | B26: https://www.gene.com/download/pdf/perjeta_prescribing.pdf | G26: AOR
A27: PHESGO Prescribing Information | B27: https://www.gene.com/download/pdf/phesgo_prescribing.pdf | G27: AOR
G28: AOR
A29: Text Links: Body
A30: LEARN MORE ABOUT PHESGO | B30: https://www.phesgo-hcp.com/dosing/dosing-administration.html | G30: AOR
A31: EXPLORE CLEOPATRA STUDY | B31: https://www.perjeta-hcp.com/metastatic/trial-design.html | G31: AOR
G32: AOR
A33: Text Links: Rep Connect URL
A34: Remove option that is not being used GET PERSONAL ASSISTANCE > REQUEST REP FOLLOW-UP > | B34: ='Production Details'!B22 -> https://oneclick.interactive.genentech.com/?ProfileId=<%= recipient.VariableField %>&BrandId=&c=<%= message.delivery.tacticCode %> | E34: Hide or delete row if not using Rep Connect CTA Remove if 3P Email | G34: DEM
A35: https://www.gene.com/privacy-policy | B35: https://www.gene.com/privacy-policy | E35: Hide or delete row if not using Rep Connect CTA Remove if 3P Email | G35: DEM
A36: Text Links: Safety
A37: www.fda.gov/medwatch | B37: https://www.fda.gov/safety/medwatch-fda-safety-information-and-adverse- event-reporting-program | G37: AOR
A38: 1-800-FDA-1088 | B38: tel:1-800-332-1088 | G38: AOR
A39: 1-888-835-2555 | B39: tel:1-888-835-2555 | G39: AOR
A40: Full Prescribing Information | B40: https://www.gene.com/download/pdf/phesgo_prescribing.pdf
...

Sheet Production Details
B1: Answers | C1: Notes | D1: Character Counter | E1: Owner
A2: Items to be completed for DEV-HANDOFF
A3: General Email/VAE Information
A4: Is the Email and/or VAE responsive? | B4: ='ProgramEmail Details'!B14 -> Yes | C4: Auto-populated from Program Details | E4: DEM
A5: Is a Third Party screenshot needed? | B5: ='ProgramEmail Details'!B15 -> Yes | C5: Auto-populated from Program Details | E5: DEM
A6: House Email Development Details
A7: Document Number: | B7: =IFERROR(VLOOKUP($A7,'Pre-Open Package'!A3:B3,2,FALSE),"") | C7: Auto-populated from Pre-Open Package tab | E7: AOR
A8: Google Drive Folder for Dev-Ready House Email Package | B8: ='CreativeLink MatrixAlt Text'!B7 -> 2 Asset Handoff | C8: Auto-populated from Creative/Link Matrix/Alt Text tab | E8: AOR
A9: House Email Asset Code | B9: =IFERROR(VLOOKUP($A9,'ProgramEmail Details'!$A:$B,2,FALSE),"") -> per-h-pmc-0001-2, per-h-pmc-0001-2-tp | C9: Auto-populated from Program Details Tab | E9: DEM
A10: Previous Asset Code | B10: =IFERROR(VLOOKUP($A10,'ProgramEmail Details'!$A:$B,2,FALSE),"") -> N/A | C10: Auto-populated from Program/Email Details tab | E10: DEM
A11: Subject Line Option 1: | B11: =IFERROR(VLOOKUP($A11,'Pre-Open Package'!A10:B12,2,FALSE),"") | C11: Auto-populated from Pre-Open Package tab | D11: =LEN(B11) -> 0 | E11: AOR
A12: Subject Line Option 2: | B12: =IFERROR(VLOOKUP($A12,'Pre-Open Package'!A11:B12,2,FALSE),"") | C12: Auto-populated from Pre-Open Package tab | D12: =LEN(B12) -> 0 | E12: AOR
A13: Subject Line Option 3: | B13: =IFERROR(VLOOKUP($A13,'Pre-Open Package'!A12:B13,2,FALSE),"") | C13: Auto-populated from Pre-Open Package tab | D13: =LEN(B13) -> 0 | E13: AOR
A14: Text version being used | C14: Only co-promote brands have been approved to use custom generic text versions. View standard text versions here. | E14: DEM
A15: Name Personalization | C15: Pulls through to Epsilon/ACM Deployment Tab Add N/A to column B if no personalization | E15: Inizio
A16: Name Personalization (Code) | B16: N/A (unless "Other" was selected for "Name Personalization") | C16: Standard name personalization code: AEM- Email Development Variables If "Other" is selected as the Personalization Field Name, coordinate variable code with Epsilon. Inizio to add code once aligned with Epsilon Pulls through to Epsilon/ACM Deployment Tab | E16: Inizio
A17: Default Name Personalization | B17: Default (or N/A if no "Name Personalization") | C17: Default: HCP FN/LN personalization default: Health Care Provider Patient FN/LN personalization default: N/A (will not use a default for patients) DEM to update if using something different. Pulls through to Epsilon/ACM Deployment Tab | E17: DEM
A18: Contact A Rep
A19: Is the Rep Connect CTA Included? | B19: ='ProgramEmail Details'!B16 -> No | C19: Auto-populated from Program Details | E19: DEM
A20: URL Format | B20: https://oneclick.interactive.genentech.com/?ProfileId=<%= recipient.VariableField %>&BrandId= | C20: Standard format, do not update | E20: Inizio
A21: CAR Brand ID Mapping | C21: If Rep Connect CTA is included, Inizio to populate CAR Brand ID from the appropriate brand tab on the Mapping Document Ensure there are no leading or trailing spaces | E21: Inizio
A22: Final URL | B22: =CONCATENATE(B20,B21,"&c=<%= message.delivery.tacticCode %>") -> https://oneclick.interactive.genentech.com/?ProfileId=<%= recipient.VariableField %>&BrandId=&c=<%= message.delivery.tacticCode %> | C22: Final Rep Connect URL to be used. This value is populated on the Creative/Link Matrix/Alt Text tab | E22: Inizio
A23: VAE Development Details
A24: Document Number: | B24: =IFERROR(VLOOKUP($A24,'Pre-Open Package'!A18:B18,2,FALSE),"") | C24: Auto-populated from Pre-Open Package tab | E24: AOR
A25: Google Drive Folder for Dev-Ready VAE Package | B25: =IFERROR(VLOOKUP($A25,'CreativeLink MatrixAlt Text'!$A:$B,2,FALSE),"") -> 2 Asset Handoff | C25: Auto-populated from Creative/Link Matrix/Alt Text tab | E25: AOR
A26: VAE Email Asset Code | B26: =IFERROR(VLOOKUP($A26,'ProgramEmail Details'!$A:$B,2,FALSE),"") -> per-h-pmc-0001-1-fe | C26: Auto-populated from Program Details tab | E26: DEM
A27: Previous Asset Code | B27: =IFERROR(VLOOKUP($A27,'ProgramEmail Details'!$A:$B,2,FALSE),"") -> N/A | C27: Auto-populated from Program/Email Details tab | E27: DEM
A28: Subject Line Option 1: | B28: =IFERROR(VLOOKUP($A28,'Pre-Open Package'!A25:B27,2,FALSE),"") | C28: Auto-populated from Pre-Open Package tab | D28: =LEN(B28) -> 0 | E28: AOR
A29: Subject Line Option 2: | B29: =IFERROR(VLOOKUP($A29,'Pre-Open Package'!A26:B28,2,FALSE),"") | C29: Auto-populated from Pre-Open Package tab | D29: =LEN(B29) -> 0 | E29: AOR
A30: Subject Line Option 3: | B30: =IFERROR(VLOOKUP($A30,'Pre-Open Package'!A27:B29,2,FALSE),"") | C30: Auto-populated from Pre-Open Package tab | D30: =LEN(B30) -> 0 | E30: AOR
A31: VAE Tactic Code | C31: Inizio to populate VAE tactic code once created | E31: Inizio
A32: Items to be completed for DEPLOY-HANDOFF *AFD'd subject lines & tactic codes for cadenced/real-time emails to be completed in the Fulfillment Details gSheet - "Fulfillment Matrix" tab.
A33: Email Deployment Details
A34: Google Drive Folder for House Email's AFD File | B34: =IFERROR(VLOOKUP($A34,'CreativeLink MatrixAlt Text'!$A:$B,2,FALSE),"") -> 4. PRC_RegA_FDA | C34: Auto-populated from Creative/Link Matrix/Alt Text tab | E34: AOR
A35: HCP Email Rating | C35: Provide rating for all HCP emails. Leverage this article to identify your email's rating. | E35: DEM
A36: Event based email? If yes provide event date (future dates only) | C36: If Event based email mark yes and provide event date. Email continues to run for 30 days until all qualified HCPs have recieved unless it is an event based email wherein the email will run until 1 day prior to the event. | E36: DEM
A37: Ad Hoc FINAL House Email Deployment Subject Line A If no A/B test, use this line for Subject Line | C37: Add this information post AFD | D37: =LEN(B37) -> 0 | E37: DEM
A38: Ad Hoc FINAL House Email Deployment Subject Line B | C38: Add this information post AFD | D38: =LEN(B38) -> 0 | E38: DEM
A39: Redeploy Subject Line | C39: Only populate if redeploy | D39: =LEN(B39) -> 0 | E39: DEM
A40: REMINDER: Review and update topic tags as needed | E40: DEM
...

Sheet Deployment Details
A1: Deployment Details
A2: Text Version | B2: Answers | C2: Notes | D2: Owner | E2: Rules
A3: Text version being used | B3: =IFERROR(VLOOKUP($A3,'Production Details'!$A:$B,2,FALSE),"") | C3: Auto-populated from Production Details tab | D3: DEM
A4: Name Personalization | B4: Answers | C4: Notes | D4: Owner | E4: Rules
A5: Name Personalization | B5: =IFERROR(VLOOKUP($A5,'Production Details'!$A:$B,2,FALSE),"") | C5: Inizio/Epsilon to coordinate variables Auto-populated from Production Details tab. | D5: Inizio | E5: If not matching AFD file, Epsilon tag Inizio to update
A6: Name Personalization (Code) | B6: =IFERROR(VLOOKUP($A6,'Production Details'!$A:$B,2,FALSE),"") -> N/A (unless "Other" was selected for "Name Personalization") | C6: Standard name personalization code: AEM- Email Development Variables If "Other" is selected as the Personalization Field Name, coordinate variable code with Epsilon Auto-populated from Production Details tab | D6: Inizio/Epsilon
A7: Default Name Personalization | B7: =IFERROR(VLOOKUP($A7,'Production Details'!$A:$B,2,FALSE),"") -> Default (or N/A if no "Name Personalization") | C7: Auto-populated from Production Details tab. HCP FN/LN personalization default: Health Care Provider Patient FN/LN personalization default: N/A (will not use a default for patients) | D7: DEM
A8: Dynamic Content | B8: Answers | C8: Notes | D8: Owner | E8: Rules
A9: Project Brief | B9: =IFERROR(VLOOKUP($A9,'ProgramEmail Details'!$A:$B,2,FALSE),"") | C9: Auto-populated from Program Details | D9: DEM
A10: Estimated Dynamic Content Variables Count | B10: =IFERROR(VLOOKUP($A10,'ProgramEmail Details'!$A:$B,2,FALSE),"") | C10: Auto-populated from Program Details. Discuss with DEM if there is any concern. | D10: DEM | E10: Max number of Dynamic Content Variables is 50. Example: 26
A11: FINAL Dynamic Content Variables Count | C11: Email AM to populate once final count has been determined after dynamic content fields have been shared by DEM | D11: Epsilon | E11: Max number of Dynamic Content Variables is 50. Example: 26
A12: Dynamic Content Criteria (Code) | B12: Links to "Dynamic Variable Codes" tab | C12: Codes can be lengthy, therefore there is a separate tab in this ERB where the codes will be input by Epsilon; that tab is linked here | D12: Epsilon | E12: Epsilon can only complete once Dynamic Content fields have been provided
A13: Dynamic Content Test Plan | B13: <Link to test case gSheet> | C13: Campaign AM to link here once shared with DEM | D13: Epsilon
A14: Engine Details | B14: Answers | C14: Notes | D14: Owner | E14: Rules
A15: HCP Email Rating | B15: =IFERROR(VLOOKUP($A15,'Production Details'!$A:$B,2,FALSE),"") | C15: Auto-populated from Production Details tab | D15: DEM
A16: Event based email? If yes provide event date (future dates only) | B16: =IFERROR(VLOOKUP($A16,'Production Details'!$A:$B,2,FALSE),"") | C16: Auto-populated from Production Details tab | D16: DEM
A17: Ad Hoc Testing Specifications | B17: Answers | C17: Notes | D17: Owner
A18: Will email have an A/B test? | B18: =IFERROR(VLOOKUP($A18,'ProgramEmail Details'!$A:$B,2,FALSE),"") | C18: Auto-populated from Program Details. Discuss with DEM if there is any concern. | D18: DEM
A19: Test Plan | B19: =IFERROR(VLOOKUP($A19,'ProgramEmail Details'!$A:$B,2,FALSE),"") | C19: Auto-populated from Program Details. Discuss with DEM if there is any concern. | D19: DEM
A20: Test List Size | B20: =IFERROR(VLOOKUP($A20,'ProgramEmail Details'!$A:$B,2,FALSE),"") | C20: Auto-populated from Program Details. Discuss with DEM if there is any concern. | D20: DEM
A21: Subject Lines | B21: Answers | C21: Notes | D21: Owner | E21: Rules
A22: Ad Hoc FINAL House Email Deployment Subject Line A If no A/B test, use this line for Subject Line | B22: =IFERROR(VLOOKUP($A22,'Production Details'!$A:$B,2,FALSE),"") | C22: Auto-populated from Production Details tab. | D22: DEM
A23: Ad Hoc FINAL House Email Deployment Subject Line B | B23: =IFERROR(VLOOKUP($A23,'Production Details'!$A:$B,2,FALSE),"") | C23: Auto-populated from Production Details tab. | D23: DEM
A24: Ad Hoc Subject Line W Winning subject line from A/B test | D24: Epsilon
A25: Redeploy Subject Line | B25: =IFERROR(VLOOKUP($A25,'Production Details'!$A:$B,2,FALSE),"") | C25: Auto-populated from Production Details tab. | D25: DEM
A26: Target Audience | D26: Owner | E26: Rules
A27: Override Domain 'Email Type' Suppression? (N/A for VAE) Should be 'No' unless this is a PAYUHCPRM or Cross-Portfolio safety and disaster email deployment that requires an exception | B27: =IFERROR(VLOOKUP($A27,'ProgramEmail Details'!$A:$B,2,FALSE),"") -> No | C27: Auto-populated from Program Details tab. Discuss with DEM if there is any concern. | D27: DEM | E27: If this is a PAYUHCPRM or Cross-Portfolio safety and disaster email deployment and DEM is unsure if it should have an exception to this suppression, DEM should partner with XO Leadership
A28: Ad Hoc List or CDP Audience Activation? Omni use cases will always use CDP and will not use an ad hoc list | B28: =IFERROR(VLOOKUP($A28,'ProgramEmail Details'!$A:$B,2,FALSE),"") | C28: Auto-populated from Program Details tab. Discuss with DEM if there is any concern. | D28: DEM
A29: Ad Hoc List Name (N/A for VAEs & CDP Audience Activation) | B29: =IFERROR(VLOOKUP($A29,'ProgramEmail Details'!$A:$B,2,FALSE),"") | C29: Auto-populated from Program Details tab. Discuss with DEM if there is any concern. | D29: DEM
A30: Ad Hoc Fulfillment Rules (N/A for VAEs & CDP Audience Activation) | B30: =IFERROR(VLOOKUP($A30,'ProgramEmail Details'!$A:$B,2,FALSE),"") | C30: Auto-populated from Program Details tab. Discuss with DEM if there is any concern. | D30: DEM
A31: Slug Value to Tactic Code (N/A for Ad Hoc Lists & VAEs) | C31: CDP AM to populate | D31: Epsilon
A32: Codes | B32: Answers | C32: Notes | D32: Owner | E32: Rules
A33: House Email Asset Code | B33: =IFERROR(VLOOKUP($A33,'ProgramEmail Details'!$A:$B,2,FALSE),"") -> per-h-pmc-0001-2, per-h-pmc-0001-2-tp | C33: Auto-populated from Program Details tab. | D33: DEM
A34: Email Name | B34: =IFERROR(VLOOKUP($A34,'ProgramEmail Details'!$A:$B,2,FALSE),"") -> Perjeta/Phesgo Dual Micro Campaign (Label Update) | C34: Auto-populated from Program Details tab. | D34: DEM
A35: Plan Code | D35: Epsilon
A36: Plan Description | D36: Epsilon
A37: Program Code | D37: Epsilon
A38: Program Description | D38: Epsilon
A39: Email Marketing Unit | B39: =IFERROR(VLOOKUP($A39,'ProgramEmail Details'!$A:$B,2,FALSE),"") -> Phesgo/Perjeta | C39: Auto-populated from Program/Email Details tab | D39: DEM
A40: Ad Hoc Tactic Code A If no A/B test, use this line | D40: Epsilon
...

Sheet GNE Validation
A1: GNE Validation / Links & Alt-Tags Matrix - DEM Owner All relevant fields must be complete and accurate prior to DEV-READY HANDOFF, and AFD'd and validated prior to DEPLOY-READY HANDOFF
A2: Email Specifics | B2: Answers DO NOT POPULATE - Answers in grey cells are autopopulated from other tabs | C2: Notes
A3: Is the Email and/or VAE responsive? | B3: =IFERROR(VLOOKUP($A3,'ProgramEmail Details'!$A:$B,2,FALSE),"") -> Yes
A4: Text version being used | B4: =IFERROR(VLOOKUP($A4,'Production Details'!$A:$B,2,FALSE),"")
A5: Ad Hoc Validation
A6: Ad Hoc FINAL House Email Deployment Subject Line A If no A/B test, use this line for Subject Line | B6: =IFERROR(VLOOKUP($A6,'Production Details'!$A:$B,2,FALSE),"") | C6: Pulled from Production Details tab
A7: Ad Hoc FINAL House Email Deployment Subject Line B | B7: =IFERROR(VLOOKUP($A7,'Production Details'!$A:$B,2,FALSE),"") | C7: Pulled from Production Details tab
A8: Ad Hoc Subject Line W Winning subject line from A/B test | B8: =IFERROR(VLOOKUP($A8,'Deployment Details'!$A:$B,2,FALSE),"") | C8: Pulled from Deployment Details tab
A9: Redeploy Subject Line | B9: =IFERROR(VLOOKUP($A9,'Deployment Details'!$A:$B,2,FALSE),"") | C9: Only populated for redeploys
A10: Ad Hoc Tactic Code A If no A/B test, use this line | B10: =IFERROR(VLOOKUP($A10,'Deployment Details'!$A:$B,2,FALSE),"") | C10: Pulled from Deploymet Details tab If no A/B, this line is the tactic code
A11: Ad Hoc Tactic Code B | B11: =IFERROR(VLOOKUP($A11,'Deployment Details'!$A:$B,2,FALSE),"") | C11: Pulled from Deploymet Details tab
A12: Ad Hoc Tactic Code W Tactic code for winner deployment from A/B test | B12: =IFERROR(VLOOKUP($A12,'Deployment Details'!$A:$B,2,FALSE),"") | C12: Pulled from Deployment Details tab
A13: Ad Hoc Redeploy Tactic Code | B13: =IFERROR(VLOOKUP($A13,'Deployment Details'!$A:$B,2,FALSE),"") | C13: Pulled from Deployment Details tab Only populated for redeploys
A14: Google Drive Folder for House Email's AFD File | B14: =IFERROR(VLOOKUP($A14,'CreativeLink MatrixAlt Text'!$A:$B,2,FALSE),"") -> 4. PRC_RegA_FDA | C14: Pulled from Creative/Link Matrix/Alt Text tab
A15: Personalization Field Name | B15: =IFERROR(VLOOKUP($A15,'Production Details'!$A:$B,2,FALSE),"") | C15: Pulled from Production Details tab
A16: Default Personalization | B16: =IFERROR(VLOOKUP($A16,'Production Details'!$A:$B,2,FALSE),"") | C16: Pulled from Production Details tab
A17: Apply Hover State to Buttons Note: Recommended for emails where visual accessibility is a priority | B17: =IFERROR(VLOOKUP($A17,'CreativeLink MatrixAlt Text'!$A:$B,2,FALSE),"") -> no | C17: Pulled from Creative/Link Matrix/Alt Text tab Only populated when emails are focused on visual accessibility
A18: Hover State Color - Hex Value | B18: =IFERROR(VLOOKUP($A18,'CreativeLink MatrixAlt Text'!$A:$B,2,FALSE),"") | C18: Pulled from Creative/Link Matrix/Alt Text tab Only populated when emails are focused on visual accessibility
A20: VAE Specifics | B20: Answers DO NOT POPULATE - Answers in grey cells are autopopulated from other tabs | C20: Notes
A21: Google Drive Folder for VAE Email's AFD File | B21: =IFERROR(VLOOKUP($A21,'CreativeLink MatrixAlt Text'!$A:$B,2,FALSE),"") | C21: Pulled from Creative/Link Matrix/Alt Text tab
A22: FINAL VAE Subject Line 1 | B22: =IFERROR(VLOOKUP($A22,'Production Details'!$A:$B,2,FALSE),"") | C22: Pulled from Production Details tab
A23: FINAL VAE Subject Line 2 | B23: =IFERROR(VLOOKUP($A23,'Production Details'!$A:$B,2,FALSE),"") | C23: Pulled from Production Details tab
A24: FINAL VAE Subject Line 3 | B24: =IFERROR(VLOOKUP($A24,'Production Details'!$A:$B,2,FALSE),"") | C24: Pulled from Production Details tab
A25: Is the Email and/or VAE responsive? | B25: =IFERROR(VLOOKUP($A25,'Production Details'!$A:$B,2,FALSE),"") -> Yes | C25: Pulled from Production Details tab
A26: VAE Template Name | B26: =IFERROR(VLOOKUP($A26,'Production Details'!$A:$B,2,FALSE),"") | C26: Pulled from Production Details tab This is what will appear in the VAE that field users will see.
A27: VAE Email Fragment 1 Name | B27: =IFERROR(VLOOKUP($A27,'Production Details'!$A:$B,2,FALSE),"") | C27: Pulled from Production Details tab This is what will appear in the VAE that field users will see.
A28: VAE Email Fragment 2 Name | B28: =IFERROR(VLOOKUP($A28,'Production Details'!$A:$B,2,FALSE),"") | C28: Pulled from Production Details tab This is what will appear in the VAE that field users will see.
A29: VAE Tactic Code | B29: =IFERROR(VLOOKUP($A29,'Production Details'!$A:$B,2,FALSE),"") | C29: Pulled from Production Details tab

Sheet Deployment Details - Dynamic Va
A1: Epsilon to populate this tab based on details provided in the Project Brief/ERB
